<?xml version="1.0" ?>
<!-- =================================================================================== -->
<!-- |    This document was autogenerated by xacro from urdfgenesyssw.xacro            | -->
<!-- |    EDITING THIS FILE BY HAND IS NOT RECOMMENDED                                 | -->
<!-- =================================================================================== -->
<!-- This URDF was automatically created by SolidWorks to URDF Exporter! Originally created by Stephen Brawner (brawner@gmail.com) 
     Commit Version: 1.5.1-0-g916b5db  Build Version: 1.5.7152.31018
     For more information, please see http://wiki.ros.org/sw_urdf_exporter -->
<robot name="urdfgenesyssw" xmlns:xacro="http://www.ros.org/wiki/xacro">
  <gazebo>
    <plugin filename="libgazebo_ros_control.so" name="gazebo_ros_control">
      <robotSimType>gazebo_ros_control/DefaultRobotHWSim</robotSimType>
      <legacyModeNS>true</legacyModeNS>
    </plugin>
  </gazebo>
  <link name="BL">
    <inertial>
      <origin rpy="0 0 0" xyz="0 0 0"/>
      <mass value="1.3732"/>
      <inertia ixx="0.0045942" ixy="0" ixz="0" iyy="0.0053191" iyz="0" izz="0.0098794"/>
    </inertial>
    <visual>
      <origin rpy="0 0 0" xyz="0 0 0"/>
      <geometry>
        <mesh filename="package://urdfgenesyssw/meshes/BL.STL"/>
      </geometry>
      <material name="">
        <color rgba="0.89804 0.91765 0.92941 1"/>
      </material>
    </visual>
    <collision>
      <origin rpy="0 0 0" xyz="0 0 0"/>
      <geometry>
        <mesh filename="package://urdfgenesyssw/meshes/BL.STL"/>
      </geometry>
    </collision>
  </link>
  <link name="LFT">
    <inertial>
      <origin rpy="0 0 0" xyz="0 -0.085 0"/>
      <mass value="0.038416"/>
      <inertia ixx="0.00010326" ixy="0" ixz="0" iyy="1.3494E-06" iyz="0" izz="0.00010451"/>
    </inertial>
    <visual>
      <origin rpy="0 0 0" xyz="0 0 0"/>
      <geometry>
        <mesh filename="package://urdfgenesyssw/meshes/LFT.STL"/>
      </geometry>
      <material name="">
        <color rgba="0.89804 0.91765 0.92941 1"/>
      </material>
    </visual>
    <collision>
      <origin rpy="0 0 0" xyz="0 0 0"/>
      <geometry>
        <mesh filename="package://urdfgenesyssw/meshes/LFT.STL"/>
      </geometry>
    </collision>
  </link>
  <joint name="BLLFT" type="revolute">
    <origin rpy="1.5708 0.7854 0" xyz="0.1 0.102 0"/>
    <parent link="BL"/>
    <child link="LFT"/>
    <axis xyz="0 0 1"/>
    <limit effort="100" lower="-0.7854" upper="0.7854" velocity="100"/>
  </joint>
  <link name="LFC">
    <inertial>
      <origin rpy="0 0 0" xyz="0 -0.085 0"/>
      <mass value="0.038416"/>
      <inertia ixx="0.00010326" ixy="0" ixz="0" iyy="1.3494E-06" iyz="0" izz="0.00010451"/>
    </inertial>
    <visual>
      <origin rpy="0 0 0" xyz="0 0 0"/>
      <geometry>
        <mesh filename="package://urdfgenesyssw/meshes/LFC.STL"/>
      </geometry>
      <material name="">
        <color rgba="0.89804 0.91765 0.92941 1"/>
      </material>
    </visual>
    <collision>
      <origin rpy="0 0 0" xyz="0 0 0"/>
      <geometry>
        <mesh filename="package://urdfgenesyssw/meshes/LFC.STL"/>
      </geometry>
    </collision>
  </link>
  <joint name="LFTLFC" type="revolute">
    <origin rpy="0 0 1.5708" xyz="0 -0.17 0.004"/>
    <parent link="LFT"/>
    <child link="LFC"/>
    <axis xyz="0 0 1"/>
    <limit effort="100" lower="-0.7854" upper="0.7854" velocity="100"/>
  </joint>
  <link name="LHT">
    <inertial>
      <origin rpy="0 0 0" xyz="0 -0.085 0"/>
      <mass value="0.038416"/>
      <inertia ixx="0.00010326" ixy="0" ixz="0" iyy="1.3494E-06" iyz="0" izz="0.00010451"/>
    </inertial>
    <visual>
      <origin rpy="0 0 0" xyz="0 0 0"/>
      <geometry>
        <mesh filename="package://urdfgenesyssw/meshes/LHT.STL"/>
      </geometry>
      <material name="">
        <color rgba="0.89804 0.91765 0.92941 1"/>
      </material>
    </visual>
    <collision>
      <origin rpy="0 0 0" xyz="0 0 0"/>
      <geometry>
        <mesh filename="package://urdfgenesyssw/meshes/LHT.STL"/>
      </geometry>
    </collision>
  </link>
  <joint name="BLLHT" type="revolute">
    <origin rpy="1.5708 0.7854 0" xyz="-0.1 0.102 0"/>
    <parent link="BL"/>
    <child link="LHT"/>
    <axis xyz="0 0 1"/>
    <limit effort="100" lower="-0.7854" upper="0.7854" velocity="100"/>
  </joint>
  <link name="LHC">
    <inertial>
      <origin rpy="0 0 0" xyz="0 -0.085 0"/>
      <mass value="0.038416"/>
      <inertia ixx="0.00010326" ixy="0" ixz="0" iyy="1.3494E-06" iyz="0" izz="0.00010451"/>
    </inertial>
    <visual>
      <origin rpy="0 0 0" xyz="0 0 0"/>
      <geometry>
        <mesh filename="package://urdfgenesyssw/meshes/LHC.STL"/>
      </geometry>
      <material name="">
        <color rgba="0.89804 0.91765 0.92941 1"/>
      </material>
    </visual>
    <collision>
      <origin rpy="0 0 0" xyz="0 0 0"/>
      <geometry>
        <mesh filename="package://urdfgenesyssw/meshes/LHC.STL"/>
      </geometry>
    </collision>
  </link>
  <joint name="LHTLHC" type="revolute">
    <origin rpy="0 0 1.5708" xyz="0 -0.17 0.004"/>
    <parent link="LHT"/>
    <child link="LHC"/>
    <axis xyz="0 0 1"/>
    <limit effort="100" lower="-0.7854" upper="0.7854" velocity="100"/>
  </joint>
  <link name="RFT">
    <inertial>
      <origin rpy="0 0 0" xyz="0 -0.085 0"/>
      <mass value="0.038416"/>
      <inertia ixx="0.00010326" ixy="0" ixz="0" iyy="1.3494E-06" iyz="0" izz="0.00010451"/>
    </inertial>
    <visual>
      <origin rpy="0 0 0" xyz="0 0 0"/>
      <geometry>
        <mesh filename="package://urdfgenesyssw/meshes/RFT.STL"/>
      </geometry>
      <material name="">
        <color rgba="0.89804 0.91765 0.92941 1"/>
      </material>
    </visual>
    <collision>
      <origin rpy="0 0 0" xyz="0 0 0"/>
      <geometry>
        <mesh filename="package://urdfgenesyssw/meshes/RFT.STL"/>
      </geometry>
    </collision>
  </link>
  <joint name="BLRFT" type="revolute">
    <origin rpy="1.5708 0.7854 0" xyz="0.1 -0.102 0"/>
    <parent link="BL"/>
    <child link="RFT"/>
    <axis xyz="0 0 1"/>
    <limit effort="100" lower="-0.7854" upper="0.7854" velocity="100"/>
  </joint>
  <link name="RFC">
    <inertial>
      <origin rpy="0 0 0" xyz="0 -0.085 0"/>
      <mass value="0.038416"/>
      <inertia ixx="0.00010326" ixy="0" ixz="0" iyy="1.3494E-06" iyz="0" izz="0.00010451"/>
    </inertial>
    <visual>
      <origin rpy="0 0 0" xyz="0 0 0"/>
      <geometry>
        <mesh filename="package://urdfgenesyssw/meshes/RFC.STL"/>
      </geometry>
      <material name="">
        <color rgba="0.89804 0.91765 0.92941 1"/>
      </material>
    </visual>
    <collision>
      <origin rpy="0 0 0" xyz="0 0 0"/>
      <geometry>
        <mesh filename="package://urdfgenesyssw/meshes/RFC.STL"/>
      </geometry>
    </collision>
  </link>
  <joint name="RFTRFC" type="revolute">
    <origin rpy="0 0 1.5708" xyz="0 -0.17 -0.004"/>
    <parent link="RFT"/>
    <child link="RFC"/>
    <axis xyz="0 0 1"/>
    <limit effort="100" lower="-0.7854" upper="0.7854" velocity="100"/>
  </joint>
  <link name="RHT">
    <inertial>
      <origin rpy="0 0 0" xyz="0 -0.085 0"/>
      <mass value="0.038416"/>
      <inertia ixx="0.00010326" ixy="0" ixz="0" iyy="1.3494E-06" iyz="0" izz="0.00010451"/>
    </inertial>
    <visual>
      <origin rpy="0 0 0" xyz="0 0 0"/>
      <geometry>
        <mesh filename="package://urdfgenesyssw/meshes/RHT.STL"/>
      </geometry>
      <material name="">
        <color rgba="0.89804 0.91765 0.92941 1"/>
      </material>
    </visual>
    <collision>
      <origin rpy="0 0 0" xyz="0 0 0"/>
      <geometry>
        <mesh filename="package://urdfgenesyssw/meshes/RHT.STL"/>
      </geometry>
    </collision>
  </link>
  <joint name="BLRHT" type="revolute">
    <origin rpy="1.5708 0.7854 0" xyz="-0.1 -0.102 0"/>
    <parent link="BL"/>
    <child link="RHT"/>
    <axis xyz="0 0 1"/>
    <limit effort="100" lower="-0.7854" upper="0.7854" velocity="100"/>
  </joint>
  <link name="RHC">
    <inertial>
      <origin rpy="0 0 0" xyz="0 -0.085 0"/>
      <mass value="0.038416"/>
      <inertia ixx="0.00010326" ixy="0" ixz="0" iyy="1.3494E-06" iyz="0" izz="0.00010451"/>
    </inertial>
    <visual>
      <origin rpy="0 0 0" xyz="0 0 0"/>
      <geometry>
        <mesh filename="package://urdfgenesyssw/meshes/RHC.STL"/>
      </geometry>
      <material name="">
        <color rgba="0.89804 0.91765 0.92941 1"/>
      </material>
    </visual>
    <collision>
      <origin rpy="0 0 0" xyz="0 0 0"/>
      <geometry>
        <mesh filename="package://urdfgenesyssw/meshes/RHC.STL"/>
      </geometry>
    </collision>
  </link>
  <joint name="RHTRHC" type="revolute">
    <origin rpy="0 0 1.5708" xyz="0 -0.17 -0.004"/>
    <parent link="RHT"/>
    <child link="RHC"/>
    <axis xyz="0 0 1"/>
    <limit effort="100" lower="-0.7854" upper="0.7854" velocity="100"/>
  </joint>
  <transmission name="BLLFT_trans">
    <type>transmission_interface/SimpleTransmission</type>
    <joint name="BLLFT">
      <hardwareInterface>hardware_interface/EffortJointInterface</hardwareInterface>
    </joint>
    <actuator name="BLLFT_motor">
      <hardwareInterface>hardware_interface/EffortJointInterface</hardwareInterface>
      <mechanicalReduction>1</mechanicalReduction>
    </actuator>
  </transmission>
  <transmission name="LFTLFC_trans">
    <type>transmission_interface/SimpleTransmission</type>
    <joint name="LFTLFC">
      <hardwareInterface>hardware_interface/EffortJointInterface</hardwareInterface>
    </joint>
    <actuator name="LFTLFC_motor">
      <hardwareInterface>hardware_interface/EffortJointInterface</hardwareInterface>
      <mechanicalReduction>1</mechanicalReduction>
    </actuator>
  </transmission>
  <transmission name="BLLHT_trans">
    <type>transmission_interface/SimpleTransmission</type>
    <joint name="BLLHT">
      <hardwareInterface>hardware_interface/EffortJointInterface</hardwareInterface>
    </joint>
    <actuator name="BLLHT_motor">
      <hardwareInterface>hardware_interface/EffortJointInterface</hardwareInterface>
      <mechanicalReduction>1</mechanicalReduction>
    </actuator>
  </transmission>
  <transmission name="LHTLHC_trans">
    <type>transmission_interface/SimpleTransmission</type>
    <joint name="LHTLHC">
      <hardwareInterface>hardware_interface/EffortJointInterface</hardwareInterface>
    </joint>
    <actuator name="LHTLHC_motor">
      <hardwareInterface>hardware_interface/EffortJointInterface</hardwareInterface>
      <mechanicalReduction>1</mechanicalReduction>
    </actuator>
  </transmission>
  <transmission name="BLRFT_trans">
    <type>transmission_interface/SimpleTransmission</type>
    <joint name="BLRFT">
      <hardwareInterface>hardware_interface/EffortJointInterface</hardwareInterface>
    </joint>
    <actuator name="BLRFT_motor">
      <hardwareInterface>hardware_interface/EffortJointInterface</hardwareInterface>
      <mechanicalReduction> 1 </mechanicalReduction>
    </actuator>
  </transmission>
  <transmission name="RFTRFC_trans">
    <type>transmission_interface/SimpleTransmission</type>
    <joint name="RFTRFC">
      <hardwareInterface>hardware_interface/EffortJointInterface</hardwareInterface>
    </joint>
    <actuator name="RFTRFC_motor">
      <hardwareInterface>hardware_interface/EffortJointInterface</hardwareInterface>
      <mechanicalReduction> 1 </mechanicalReduction>
    </actuator>
  </transmission>
  <transmission name="BLRHT_trans">
    <type>transmission_interface/SimpleTransmission</type>
    <joint name="BLRHT">
      <hardwareInterface>hardware_interface/EffortJointInterface</hardwareInterface>
    </joint>
    <actuator name="BLRHT_motor">
      <hardwareInterface>hardware_interface/EffortJointInterface</hardwareInterface>
      <mechanicalReduction> 1 </mechanicalReduction>
    </actuator>
  </transmission>
  <transmission name="RHTRHC_trans">
    <type>transmission_interface/SimpleTransmission</type>
    <joint name="RHTRHC">
      <hardwareInterface>hardware_interface/EffortJointInterface</hardwareInterface>
    </joint>
    <actuator name="RHTRHC_motor">
      <hardwareInterface>hardware_interface/EffortJointInterface</hardwareInterface>
      <mechanicalReduction> 1 </mechanicalReduction>
    </actuator>
  </transmission>
</robot>

